<mujoco model="panda">
  <compiler angle="radian" autolimits="true"/>
  <option integrator="implicitfast" timestep="0.005"/>

  <worldbody>
    <light pos="1 1 2" mode="trackcom"/>
    <geom type="plane" size="1.5 1.5 0.05" rgba="0.25 0.25 0.3 1"/>

    <body name="link0" pos="0 0 0">
      <inertial mass="0.629769" pos="-0.041018 -0.00014 0.049974"
        fullinertia="0.00315 0.00388 0.004285 8.2904e-7 0.00015 8.2299e-6"/>
      <geom type="cylinder" size="0.11 0.06" fromto="0 0 0 0 0 0.06" rgba="0.75 0.75 0.75 1"/>
      <geom type="cylinder" size="0.09 0.02" fromto="0 0 0.06 0 0 0.08" rgba="0.3 0.3 0.3 1"/>

      <body name="link1" pos="0 0 0.333">
        <inertial mass="4.970684" pos="0.003875 0.002081 -0.04762"
          fullinertia="0.70337 0.70661 0.0091170 -0.00013900 0.0067720 0.019169"/>
        <joint name="joint1" type="hinge" axis="0 0 1" range="-2.8973 2.8973" armature="0.1" damping="1"/>
        <geom type="cylinder" size="0.07 0.18" fromto="0 0 -0.05 0 0 0.27" rgba="0.45 0.5 0.6 1"/>

        <body name="link2" pos="0 0 0.316" quat="0.7071 -0.7071 0 0">
          <inertial mass="0.646926" pos="-0.003141 -0.02872 0.003495"
            fullinertia="0.0079620 2.8110e-2 2.5995e-2 -3.925e-3 1.0254e-2 7.04e-4"/>
          <joint name="joint2" axis="0 0 1" range="-1.7628 1.7628" armature="0.1" damping="1"/>
          <geom type="cylinder" size="0.06 0.18" fromto="0 0 -0.28 0 0 0.04" rgba="0.4 0.45 0.55 1"/>

          <body name="link3" pos="0 -0.316 0" quat="0.7071 0.7071 0 0">
            <inertial mass="3.228604" pos="2.7518e-2 3.9252e-2 -6.6502e-2"
              fullinertia="3.7242e-2 3.6155e-2 1.083e-2 -4.761e-3 -1.1396e-2 -1.2805e-2"/>
            <joint name="joint3" axis="0 0 1" range="-2.8973 2.8973" armature="0.1" damping="1"/>
            <geom type="cylinder" size="0.05 0.16" fromto="0 0 -0.04 0 0 0.12" rgba="0.4 0.45 0.55 1"/>

            <body name="link4" pos="0.0825 0 0" quat="0.7071 0.7071 0 0">
              <inertial mass="3.587895" pos="-5.317e-2 1.04419e-1 2.7454e-2"
                fullinertia="2.5853e-2 1.9552e-2 2.8323e-2 7.796e-3 -1.332e-3 8.641e-3"/>
              <joint name="joint4" axis="0 0 1" range="-3.0718 -0.0698" armature="0.1" damping="1"/>
              <geom type="cylinder" size="0.05 0.14" fromto="-0.08 0 -0.02 -0.08 0.35 0.05" rgba="0.45 0.5 0.6 1"/>

              <body name="link5" pos="-0.0825 0.384 0" quat="0.7071 -0.7071 0 0">
                <inertial mass="1.225946" pos="-1.1953e-2 4.1065e-2 -3.8437e-2"
                  fullinertia="3.5549e-2 2.9474e-2 8.627e-3 -2.117e-3 -4.037e-3 2.29e-4"/>
                <joint name="joint5" axis="0 0 1" range="-2.8973 2.8973" armature="0.1" damping="1"/>
                <geom type="cylinder" size="0.04 0.12" fromto="0 0.08 -0.02 0 0 0.10" rgba="0.4 0.45 0.55 1"/>

                <body name="link6" pos="0 0 0" quat="0.7071 0.7071 0 0">
                  <inertial mass="1.666555" pos="6.0149e-2 -1.4117e-2 -1.0517e-2"
                    fullinertia="1.964e-3 4.354e-3 5.433e-3 1.09e-4 -1.158e-3 3.41e-4"/>
                  <joint name="joint6" axis="0 0 1" range="-0.0175 3.7525" armature="0.1" damping="1"/>
                  <geom type="cylinder" size="0.04 0.09" fromto="0 0 0 0.08 0 0.02" rgba="0.35 0.4 0.5 1"/>

                  <body name="link7" pos="0.088 0 0" quat="0.7071 0.7071 0 0">
                    <inertial mass="0.735522" pos="1.0517e-2 -4.252e-3 6.1597e-2"
                      fullinertia="1.2516e-2 1.0027e-2 4.815e-3 -4.28e-4 -1.196e-3 -7.41e-4"/>
                    <joint name="joint7" axis="0 0 1" range="-2.8973 2.8973" armature="0.1" damping="1"/>
                    <geom type="cylinder" size="0.03 0.08" fromto="0 0 0 0 0 0.09" rgba="0.3 0.35 0.45 1"/>

                    <body name="hand" pos="0 0 0.107" quat="0.92388 0 0 -0.38268">
                      <inertial mass="0.73" pos="-0.01 0 0.03" diaginertia="0.001 0.0025 0.0017"/>
                      <geom type="box" size="0.04 0.07 0.03" pos="0 0 0.015" rgba="0.55 0.55 0.6 1"/>

                      <body name="left_finger" pos="0 0 0.0584">
                        <inertial mass="0.015" pos="0 0 0" diaginertia="2.375e-6 2.375e-6 7.5e-7"/>
                        <joint name="finger_joint1" type="slide" axis="0 1 0" range="0 0.04" armature="0.1" damping="1"/>
                        <geom type="capsule" size="0.008 0.025" fromto="0 0 0 0 0 0.04" rgba="0.85 0.3 0.3 1"/>
                      </body>

                      <body name="right_finger" pos="0 0 0.0584" quat="0 0 0 1">
                        <inertial mass="0.015" pos="0 0 0" diaginertia="2.375e-6 2.375e-6 7.5e-7"/>
                        <joint name="finger_joint2" type="slide" axis="0 1 0" range="0 0.04" armature="0.1" damping="1"/>
                        <geom type="capsule" size="0.008 0.025" fromto="0 0 0 0 0 0.04" rgba="0.85 0.3 0.3 1"/>
                      </body>
                    </body>
                  </body>
                </body>
              </body>
            </body>
          </body>
        </body>
      </body>
    </body>
  </worldbody>

  <actuator>
    <general name="a1" joint="joint1" dyntype="none" biastype="affine"
      gainprm="100" biasprm="0 -100 -10" ctrlrange="-2.8973 2.8973" forcerange="-87 87"/>
    <general name="a2" joint="joint2" dyntype="none" biastype="affine"
      gainprm="100" biasprm="0 -100 -10" ctrlrange="-1.7628 1.7628" forcerange="-87 87"/>
    <general name="a3" joint="joint3" dyntype="none" biastype="affine"
      gainprm="80" biasprm="0 -80 -8" ctrlrange="-2.8973 2.8973" forcerange="-87 87"/>
    <general name="a4" joint="joint4" dyntype="none" biastype="affine"
      gainprm="80" biasprm="0 -80 -8" ctrlrange="-3.0718 -0.0698" forcerange="-87 87"/>
    <general name="a5" joint="joint5" dyntype="none" biastype="affine"
      gainprm="50" biasprm="0 -50 -5" ctrlrange="-2.8973 2.8973" forcerange="-12 12"/>
    <general name="a6" joint="joint6" dyntype="none" biastype="affine"
      gainprm="50" biasprm="0 -50 -5" ctrlrange="-0.0175 3.7525" forcerange="-12 12"/>
    <general name="a7" joint="joint7" dyntype="none" biastype="affine"
      gainprm="50" biasprm="0 -50 -5" ctrlrange="-2.8973 2.8973" forcerange="-12 12"/>
  </actuator>

  <equality>
    <joint joint1="finger_joint1" joint2="finger_joint2" solimp="0.95 0.99 0.001" solref="0.005 1"/>
  </equality>

  <keyframe>
    <key name="home" qpos="0 0 0 -1.57079 0 1.57079 -0.7853 0.04 0.04"
      ctrl="0 0 0 -1.57079 0 1.57079 -0.7853"/>
  </keyframe>
</mujoco>
